Workbook

Sheet LÉEME
A1: Campañas de email L'Oréal · agosto a octubre 2025
A2: Caso DDX · María Fernanda Girón Rojas
B4: QUÉ ES ESTE ARCHIVO
B5: El análisis de 576 campañas de email enviadas entre agosto y octubre de 2025, con el detalle de qué funcionó, qué no, y qué datos no se pudieron usar.
B6: Cómo leerlo: empiece por la hoja TABLERO, que resume todo en cuatro gráficos. H0 DATOS muestra qué filas se usan y por qué se excluye el 15 %. HALLAZGOS tiene la lista de todas las hipótesis probadas, y cada una tiene su tabla y su gráfica en las hojas H1 CALENDARIO, H2 CAMPAÑA, H3 ASUNTO y H4 TEMÁTICA HOT SALE. RANKING ASUNTOS es el listado completo. DATOS LIMPIOS y FILAS EXCLUIDAS están para que cualquiera pueda auditar las cifras.
B8: LAS MÉTRICAS, EXPLICADAS
B9: Para los ejemplos: imagine que enviamos 1.000 correos, 300 personas lo abren y de esas 90 hacen clic en algún enlace.
B10: Métrica | C10: Qué responde | D10: Cómo se calcula | E10: Ejemplo | F10: Para qué sirve
B11: Tasa de Apertura | C11: De todos los que recibieron el correo, ¿cuántos lo abrieron? | D11: Aperturas ÷ Envíos | E11: 300 ÷ 1.000 = 30 % | F11: Mide si el ASUNTO fue lo bastante atractivo para ganarse el clic en la bandeja.
B12: CTR (Tasa de Clics) | C12: De todos los que recibieron el correo, ¿cuántos hicieron clic? | D12: Clics ÷ Envíos | E12: 90 ÷ 1.000 = 9 % | F12: Mide el resultado de toda la cadena: asunto más contenido, de punta a punta.
B13: CTOR (Clics por Apertura) | C13: De los que ABRIERON, ¿cuántos hicieron clic? | D13: Clics ÷ Aperturas | E13: 90 ÷ 300 = 30 % | F13: Aísla el contenido: una vez abierto el correo, ¿convenció lo de adentro?
B14: Tasa de Conversión | C14: De los que recibieron, ¿cuántos terminaron comprando? | D14: Viene en el archivo original | E14: — | F14: Es la métrica de negocio. Ojo: en estos datos no se relaciona con nada (ver TABLERO).
B15: Tasa de Desuscripción | C15: ¿Cuántos pidieron no recibir más correos? | D15: Viene en el archivo original | E15: — | F15: El costo oculto de enviar de más. Sube cuando cansamos a la base.
B16: Ingreso por mil envíos | C16: Cuánto dinero deja cada 1.000 correos enviados. | D16: Ingresos ÷ Envíos × 1.000 | E16: — | F16: Permite comparar campañas grandes con pequeñas en la misma vara.
B18: QUÉ DATOS SE DEJARON FUERA, Y POR QUÉ
B19: De las 576 filas del archivo original se excluyeron 87 (15.1 %). Ninguna se borró en silencio: la hoja FILAS EXCLUIDAS tiene cada una con su motivo y su número de fila original.
B20: Motivo | C20: Filas que rompen la regla (crudo) | D20: Filas excluidas por esta razón | E20: Por qué se excluye
B21: Imposible: más clics que aperturas | C21: 75 | D21: 72 | E21: No puede hacer clic quien no abrió. Implicaría CTOR de hasta 917 %.
B22: Fecha fuera de la ventana ago-oct 2025 | C22: 7 | D22: 7 | E22: Hay registros de 1990, 2022 y 2026. El caso pide los últimos tres meses.
B23: Imposible: más aperturas que envíos | C23: 5 | D23: 5 | E23: No puede abrir más gente de la que recibió el correo.
B24: Campos vacíos en métricas de cálculo | C24: 3 | D24: 3 | E24: Sin envíos o sin aperturas no se puede calcular ninguna tasa.
B25: Las dos columnas de número no coinciden en una fila, y es correcto: hay 3 registros que rompen DOS reglas a la vez. En la columna de exclusiones cada fila se cuenta una sola vez, bajo la primera razón que aplica. Por eso 75 filas tienen más clics que aperturas pero solo 72 se excluyen por eso: las otras 3 ya habían caído por fecha o por aperturas imposibles.
B26: Quedan 489 campañas para analizar.

Sheet TABLERO PRO
A1: Email marketing L'Oréal · agosto a octubre de 2025
A2: 489 campañas usables de 576. Todo lo que se ve son fórmulas que leen DATOS LIMPIOS: si se corrige un dato crudo, el tablero se mueve con él.
A4: CAMPAÑAS USABLES | D4: APERTURA PONDERADA | G4: LO EXPLICA EL ASUNTO | J4: COSTO DE ABRIR CON ETIQUETA | M4: …Y EN CLICS | P4: INGRESO POR CAMPAÑA CORREGIDA
A5: =COUNT('DATOS LIMPIOS'!$M$5:$M$493) -> 489 | D5: =SUM('DATOS LIMPIOS'!$H$5:$H$493)/SUM('DATOS LIMPIOS'!$G$5:$G$493)*100 -> 28.944019 | G5: =(SUMPRODUCT(('DATOS LIMPIOS'!$M$5:$M$493-AVERAGE('DATOS LIMPIOS'!$M$5:$M$493))^2)-SUMPRODUCT(('DATOS LIMPIOS'!$M$5:$M$493-'DATOS LIMPIOS'!$Q$5:$Q$493)^2))/SUMPRODUCT(('DATOS LIMPIOS'!$M$5:$M$493-AVERAGE('DATOS LIMPIOS'!$M$5:$M$493))^2)*100 -> 47.410372 | J5: =(AVERAGEIF('DATOS LIMPIOS'!$AH$5:$AH$493,"No",'DATOS LIMPIOS'!$M$5:$M$493)-AVERAGEIF('DATOS LIMPIOS'!$AH$5:$AH$493,"Sí",'DATOS LIMPIOS'!$M$5:$M$493)) -> 13.255766 | M5: =(AVERAGEIF('DATOS LIMPIOS'!$AH$5:$AH$493,"No",'DATOS LIMPIOS'!$N$5:$N$493)-AVERAGEIF('DATOS LIMPIOS'!$AH$5:$AH$493,"Sí",'DATOS LIMPIOS'!$N$5:$N$493)) -> 1.8958056 | P5: ='PROYECCIÓN COP'!$D$8*(AVERAGEIF('DATOS LIMPIOS'!$AH$5:$AH$493,"No",'DATOS LIMPIOS'!$N$5:$N$493)-AVERAGEIF('DATOS LIMPIOS'!$AH$5:$AH$493,"Sí",'DATOS LIMPIOS'!$N$5:$N$493))/100*'PROYECCIÓN COP'!$D$15/100*'PROYECCIÓN COP'!$D$16/1000000 -> 16.016744
A6: de 576; 87 con datos imposibles | D6: sobre 120,1 M de envíos | G6: el calendario no llega al 2 % | J6: de apertura · 43 asuntos contra 23 | M6: de CTR · el intervalo no toca el cero | P6: COP · rango +7,4 a +24,7 M
A8: DÓNDE ESTÁ LA PALANCA
A24: LO QUE NO MUEVE EL RESULTADO | J24: QUÉ VALE CORREGIRLO
A25: Hipótesis | E25: % que explica | G25: p
A26: El tipo de campaña | E26: =(SUMPRODUCT(('DATOS LIMPIOS'!$M$5:$M$493-AVERAGE('DATOS LIMPIOS'!$M$5:$M$493))^2)-SUMPRODUCT(('DATOS LIMPIOS'!$M$5:$M$493-'DATOS LIMPIOS'!$R$5:$R$493)^2))/SUMPRODUCT(('DATOS LIMPIOS'!$M$5:$M$493-AVERAGE('DATOS LIMPIOS'!$M$5:$M$493))^2)*100 -> 1.3828802 | G26: 0,212 | J26: Aperturas ganadas por campaña | M26: ='PROYECCIÓN COP'!$D$8*(AVERAGEIF('DATOS LIMPIOS'!$AH$5:$AH$493,"No",'DATOS LIMPIOS'!$M$5:$M$493)-AVERAGEIF('DATOS LIMPIOS'!$AH$5:$AH$493,"Sí",'DATOS LIMPIOS'!$M$5:$M$493))/100 -> 31108.764 | O26: medido; el intervalo nunca toca el cero
A27: La hora de envío | E27: ='H3 ASUNTO'!$B$12 -> 1.0467798 | G27: 0,750 | J27: Clics ganados por campaña | M27: ='PROYECCIÓN COP'!$D$8*(AVERAGEIF('DATOS LIMPIOS'!$AH$5:$AH$493,"No",'DATOS LIMPIOS'!$N$5:$N$493)-AVERAGEIF('DATOS LIMPIOS'!$AH$5:$AH$493,"Sí",'DATOS LIMPIOS'!$N$5:$N$493))/100 -> 4449.0955 | O27: medido; el intervalo tampoco lo toca
A28: El día de la semana | E28: ='H3 ASUNTO'!$B$13 -> 0.52913858 | G28: 0,860 | J28: Ingreso por campaña corregida | M28: ='PROYECCIÓN COP'!$D$8*(AVERAGEIF('DATOS LIMPIOS'!$AH$5:$AH$493,"No",'DATOS LIMPIOS'!$N$5:$N$493)-AVERAGEIF('DATOS LIMPIOS'!$AH$5:$AH$493,"Sí",'DATOS LIMPIOS'!$N$5:$N$493))/100*'PROYECCIÓN COP'!$D$15/100*'PROYECCIÓN COP'!$D$16/1000000 -> 16.016744 | O28: conversión y ticket son supuestos de marca
A29: El mes | E29: ='H3 ASUNTO'!$B$14 -> 0.09407893 | G29: 0,823 | J29: Al año, al ritmo observado | M29: ='PROYECCIÓN COP'!$D$17*COUNTIF('DATOS LIMPIOS'!$AH$5:$AH$493,"Sí")/COUNT('DATOS LIMPIOS'!$M$5:$M$493)*'PROYECCIÓN COP'!$D$8*(AVERAGEIF('DATOS LIMPIOS'!$AH$5:$AH$493,"No",'DATOS LIMPIOS'!$N$5:$N$493)-AVERAGEIF('DATOS LIMPIOS'!$AH$5:$AH$493,"Sí",'DATOS LIMPIOS'!$N$5:$N$493))/100*'PROYECCIÓN COP'!$D$15/100*'PROYECCIÓN COP'!$D$16/1000000 -> 106.90931 | O29: 27,8 % de las campañas abre con etiqueta
A30: El momento del mes (quincena) | E30: ='H3 ASUNTO'!$B$15 -> 0.17975665 | G30: 0,024 · ver nota
A31: Ninguna diferencia supera lo que mueve el azar (Kruskal-Wallis, p > 0,05). Los cinco factores juntos no explican el 3 % de la apertura. La quincena da p = 0,024 en CTR, pero se corrieron 16 pruebas (el umbral corregido es 0,003), se cae al mover la definición un día, y va al revés: el CTR es MENOR en quincena. Detalle en HALLAZGOS. | J31: Las aperturas y los clics están MEDIDOS: las dos brechas salen de comparar 353 campañas contra 136 y sus intervalos de confianza no tocan el cero. Lo que es supuesto es la conversión del clic a compra (2 %) y el ticket (180.000 COP): esas dos celdas viven en PROYECCIÓN COP y marca debe reemplazarlas por las reales.
A33: LA DECISIÓN DE MAÑANA
A34: Asuntos para RETIRAR, ya identificados | F34: =COUNTIF('BIBLIOTECA ASUNTOS'!$H$10:$H$31,"RETIRAR") -> 10 | H34: Asunto propuesto para Hot Sale | K34: Hasta 40% en tus favoritos - Hot Sale L’Oréal Paris
A35: Asuntos para REPETIR sin miedo | F35: =COUNTIF('BIBLIOTECA ASUNTOS'!$H$10:$H$31,"REPETIR") -> 12 | H35: Y el A/B que lo confirma | K35: 10 % de la base por versión · la cifra al principio contra la cifra al final
A37: EL LÍMITE, DICHO ANTES DE QUE LO PREGUNTEN. Lo que está medido es que abrir con una etiqueta cuesta apertura y clics: 43 asuntos contra 23, los tres meses, y la brecha resiste quitar cualquiera de los 66 asuntos. Lo que NO está medido es que poner una cifra en el asunto suba la apertura por sí sola: en todo el archivo hay un único asunto con cifra, así que no se puede separar «lleva número» de «es esa frase». Por eso la cifra va al A/B y no al plan. Hoja PRUEBA DE ROBUSTEZ.
A39: Dónde seguir: PRUEBA DE ROBUSTEZ para las pruebas duras · HALLAZGOS y H1 a H4 para cada hipótesis · DESCUENTO ÓPTIMO y PROYECCIÓN COP para la plata · BIBLIOTECA ASUNTOS para el asunto del próximo envío · FÓRMULAS Y VERIFICACIÓN para recalcular cada cifra.
A42: DATOS QUE ALIMENTAN LOS GRÁFICOS · fuera del área de impresión
A43: Estilo de apertura | B43: Apertura
A44: Dice qué hay dentro | B44: =AVERAGEIF('DATOS LIMPIOS'!$AH$5:$AH$493,"No",'DATOS LIMPIOS'!$M$5:$M$493) -> 32.873289
A45: Abre con etiqueta | B45: =AVERAGEIF('DATOS LIMPIOS'!$AH$5:$AH$493,"Sí",'DATOS LIMPIOS'!$M$5:$M$493) -> 19.617523
A47: Mes | B47: Dice qué hay dentro | C47: Abre con etiqueta
A48: Agosto | B48: =AVERAGEIFS('DATOS LIMPIOS'!$M$5:$M$493,'DATOS LIMPIOS'!$T$5:$T$493,"Agosto",'DATOS LIMPIOS'!$AH$5:$AH$493,"No") -> 32.555382 | C48: =AVERAGEIFS('DATOS LIMPIOS'!$M$5:$M$493,'DATOS LIMPIOS'!$T$5:$T$493,"Agosto",'DATOS LIMPIOS'!$AH$5:$AH$493,"Sí") -> 22.687529
A49: Septiembre | B49: =AVERAGEIFS('DATOS LIMPIOS'!$M$5:$M$493,'DATOS LIMPIOS'!$T$5:$T$493,"Septiembre",'DATOS LIMPIOS'!$AH$5:$AH$493,"No") -> 32.87815 | C49: =AVERAGEIFS('DATOS LIMPIOS'!$M$5:$M$493,'DATOS LIMPIOS'!$T$5:$T$493,"Septiembre",'DATOS LIMPIOS'!$AH$5:$AH$493,"Sí") -> 16.127339
A50: Octubre | B50: =AVERAGEIFS('DATOS LIMPIOS'!$M$5:$M$493,'DATOS LIMPIOS'!$T$5:$T$493,"Octubre",'DATOS LIMPIOS'!$AH$5:$AH$493,"No") -> 33.164494 | C50: =AVERAGEIFS('DATOS LIMPIOS'!$M$5:$M$493,'DATOS LIMPIOS'!$T$5:$T$493,"Octubre",'DATOS LIMPIOS'!$AH$5:$AH$493,"Sí") -> 19.532131
A52: Factor | B52: % explicado
A53: El asunto | B53: =(SUMPRODUCT(('DATOS LIMPIOS'!$M$5:$M$493-AVERAGE('DATOS LIMPIOS'!$M$5:$M$493))^2)-SUMPRODUCT(('DATOS LIMPIOS'!$M$5:$M$493-'DATOS LIMPIOS'!$Q$5:$Q$493)^2))/SUMPRODUCT(('DATOS LIMPIOS'!$M$5:$M$493-AVERAGE('DATOS LIMPIOS'!$M$5:$M$493))^2)*100 -> 47.410372
A54: El tipo de campaña | B54: =(SUMPRODUCT(('DATOS LIMPIOS'!$M$5:$M$493-AVERAGE('DATOS LIMPIOS'!$M$5:$M$493))^2)-SUMPRODUCT(('DATOS LIMPIOS'!$M$5:$M$493-'DATOS LIMPIOS'!$R$5:$R$493)^2))/SUMPRODUCT(('DATOS LIMPIOS'!$M$5:$M$493-AVERAGE('DATOS LIMPIOS'!$M$5:$M$493))^2)*100 -> 1.3828802
A55: La hora | B55: ='H3 ASUNTO'!$B$12 -> 1.0467798
A56: El día | B56: ='H3 ASUNTO'!$B$13 -> 0.52913858
A57: El mes | B57: ='H3 ASUNTO'!$B$14 -> 0.09407893

Sheet PRUEBA DE ROBUSTEZ
A1: Prueba de robustez · qué aguanta y qué no
A2: Un hallazgo que solo existe en el promedio general no sirve para decidir. Aquí se le hacen cuatro pruebas distintas y se dice dónde se rompe.
A4: EL HALLAZGO. Un asunto que abre con una etiqueta genérica («Actualización de…», «Presentamos:», «Oportunidades de…») dice qué TIPO de correo es, no qué hay adentro. Los que dicen qué hay adentro abren 13,3 puntos más. La lista de 15 etiquetas está escrita en la fórmula de la columna AH de DATOS LIMPIOS y se puede auditar palabra por palabra.
A6: A · LA MEDICIÓN
B7: Dice qué hay dentro | C7: Abre con etiqueta | D7: Brecha o total | E7: Unidad
A8: Campañas | B8: =COUNTIF('DATOS LIMPIOS'!$AH$5:$AH$493,"No") -> 353 | C8: =COUNTIF('DATOS LIMPIOS'!$AH$5:$AH$493,"Sí") -> 136 | D8: =B8+C8 -> 489 | E8: campañas en total
A9: Asuntos distintos | B9: =SUMPRODUCT(('DATOS LIMPIOS'!$AH$5:$AH$493="No")/COUNTIF('DATOS LIMPIOS'!$E$5:$E$493,'DATOS LIMPIOS'!$E$5:$E$493)) -> 43 | C9: =SUMPRODUCT(('DATOS LIMPIOS'!$AH$5:$AH$493="Sí")/COUNTIF('DATOS LIMPIOS'!$E$5:$E$493,'DATOS LIMPIOS'!$E$5:$E$493)) -> 23 | D9: =B9+C9 -> 66 | E9: asuntos en total
A10: Apertura media | B10: =AVERAGEIF('DATOS LIMPIOS'!$AH$5:$AH$493,"No",'DATOS LIMPIOS'!$M$5:$M$493) -> 32.873289 | C10: =AVERAGEIF('DATOS LIMPIOS'!$AH$5:$AH$493,"Sí",'DATOS LIMPIOS'!$M$5:$M$493) -> 19.617523 | D10: =B10-C10 -> 13.255766 | E10: puntos de brecha
A11: CTR medio | B11: =AVERAGEIF('DATOS LIMPIOS'!$AH$5:$AH$493,"No",'DATOS LIMPIOS'!$N$5:$N$493) -> 10.314437 | C11: =AVERAGEIF('DATOS LIMPIOS'!$AH$5:$AH$493,"Sí",'DATOS LIMPIOS'!$N$5:$N$493) -> 8.4186314 | D11: =B11-C11 -> 1.8958056 | E11: puntos de brecha
A13: B · ¿PUEDE SER AZAR? T DE WELCH, CALCULADA AQUÍ MISMO
A14: Paso del cálculo | B14: Apertura | C14: CTR
A15: Varianza · dice qué hay dentro | B15: =SUMPRODUCT(('DATOS LIMPIOS'!$AH$5:$AH$493="No")*('DATOS LIMPIOS'!$M$5:$M$493-$B$10)^2)/(COUNTIF('DATOS LIMPIOS'!$AH$5:$AH$493,"No")-1) -> 128.23122 | C15: =SUMPRODUCT(('DATOS LIMPIOS'!$AH$5:$AH$493="No")*('DATOS LIMPIOS'!$N$5:$N$493-$B$11)^2)/(COUNTIF('DATOS LIMPIOS'!$AH$5:$AH$493,"No")-1) -> 29.389996 | D15: SUMPRODUCT con máscara 0/1, dividido por n−1
A16: Varianza · abre con etiqueta | B16: =SUMPRODUCT(('DATOS LIMPIOS'!$AH$5:$AH$493="Sí")*('DATOS LIMPIOS'!$M$5:$M$493-$C$10)^2)/(COUNTIF('DATOS LIMPIOS'!$AH$5:$AH$493,"Sí")-1) -> 88.540649 | C16: =SUMPRODUCT(('DATOS LIMPIOS'!$AH$5:$AH$493="Sí")*('DATOS LIMPIOS'!$N$5:$N$493-$C$11)^2)/(COUNTIF('DATOS LIMPIOS'!$AH$5:$AH$493,"Sí")-1) -> 26.158632
A17: Error estándar de la brecha | B17: =SQRT(B15/$B$8+B16/$C$8) -> 1.0071224 | C17: =SQRT(C15/$B$8+C16/$C$8) -> 0.52497682 | D17: √(v₁/n₁ + v₂/n₂), sin suponer varianzas iguales
A18: t | B18: =$D$10/B17 -> 13.162021 | C18: =$D$11/C17 -> 3.6112177 | D18: la brecha dividida por su error estándar
A19: Grados de libertad (Welch-Satterthwaite) | B19: =(B15/$B$8+B16/$C$8)^2/((B15/$B$8)^2/($B$8-1)+(B16/$C$8)^2/($C$8-1)) -> 292.7305 | C19: =(C15/$B$8+C16/$C$8)^2/((C15/$B$8)^2/($B$8-1)+(C16/$C$8)^2/($C$8-1)) -> 258.58533
A20: p a dos colas | B20: =TDIST(ABS(B18),B19,2) -> 2.2189444e-31 | C20: =TDIST(ABS(C18),C19,2) -> 0.00036614835 | D20: por debajo de 0,05 el hallazgo no es azar
A22: Las dos p salen muy por debajo de 0,001. Con 353 campañas contra 136, una brecha de este tamaño no la produce el azar. Y a diferencia de lo que pasaba con la cifra en el asunto, aquí el CTR también pasa: la plata deja de depender de un supuesto.
A24: C · ¿SE SOSTIENE MES A MES, O VIVE EN EL PROMEDIO?
A25: Mes | B25: Dice qué hay dentro | C25: Abre con etiqueta | D25: Brecha | E25: Campañas del mes
A26: Agosto | B26: =AVERAGEIFS('DATOS LIMPIOS'!$M$5:$M$493,'DATOS LIMPIOS'!$T$5:$T$493,"Agosto",'DATOS LIMPIOS'!$AH$5:$AH$493,"No") -> 32.555382 | C26: =AVERAGEIFS('DATOS LIMPIOS'!$M$5:$M$493,'DATOS LIMPIOS'!$T$5:$T$493,"Agosto",'DATOS LIMPIOS'!$AH$5:$AH$493,"Sí") -> 22.687529 | D26: =B26-C26 -> 9.8678524 | E26: =COUNTIF('DATOS LIMPIOS'!$T$5:$T$493,"Agosto") -> 159
A27: Septiembre | B27: =AVERAGEIFS('DATOS LIMPIOS'!$M$5:$M$493,'DATOS LIMPIOS'!$T$5:$T$493,"Septiembre",'DATOS LIMPIOS'!$AH$5:$AH$493,"No") -> 32.87815 | C27: =AVERAGEIFS('DATOS LIMPIOS'!$M$5:$M$493,'DATOS LIMPIOS'!$T$5:$T$493,"Septiembre",'DATOS LIMPIOS'!$AH$5:$AH$493,"Sí") -> 16.127339 | D27: =B27-C27 -> 16.75081 | E27: =COUNTIF('DATOS LIMPIOS'!$T$5:$T$493,"Septiembre") -> 167
A28: Octubre | B28: =AVERAGEIFS('DATOS LIMPIOS'!$M$5:$M$493,'DATOS LIMPIOS'!$T$5:$T$493,"Octubre",'DATOS LIMPIOS'!$AH$5:$AH$493,"No") -> 33.164494 | C28: =AVERAGEIFS('DATOS LIMPIOS'!$M$5:$M$493,'DATOS LIMPIOS'!$T$5:$T$493,"Octubre",'DATOS LIMPIOS'!$AH$5:$AH$493,"Sí") -> 19.532131 | D28: =B28-C28 -> 13.632363 | E28: =COUNTIF('DATOS LIMPIOS'!$T$5:$T$493,"Octubre") -> 163
A30: Tres meses independientes, brecha positiva en los tres. El mes más flojo (agosto) sigue dando casi 10 puntos. No es un mes raro arrastrando el promedio.
A32: D · PRUEBAS QUE NO CABEN EN UNA CELDA
A33: Prueba | B33: Apertura | C33: CTR | D33: Qué la descartaría
A34: Brecha medida | B34: +13,26 pts | C34: +1,90 pts | D34: —
A35: Intervalo de confianza al 95 % · bootstrap de 20.000 remuestreos | B35: +11,25 a +15,22 | C35: +0,88 a +2,90 | D35: Que el intervalo tocara el cero. No lo toca.
A36: Probabilidad de que la brecha sea positiva | B36: 100,0 % | C36: 100,0 % | D36: Que bajara del 95 %.
A37: Deja uno fuera: la brecha quitando cada uno de los 66 asuntos, uno por uno | B37: nunca baja de +12,70 | C37: nunca baja de +1,69 | D37: Que un solo asunto sostuviera todo. Ninguno lo hace.
A38: Quitando el único asunto que lleva cifra | B38: +12,70 pts | C38: +1,88 pts | D38: Que este hallazgo fuera el de la cifra disfrazado. No lo es.
A39: Mann-Whitney contando cada asunto una vez, no cada campaña | B39: p < 0,00001 | C39: — | D39: Que la brecha viniera de repetir mucho unos pocos asuntos.
A41: Estas seis filas se calculan en fuente/robustez-etiqueta.py con semilla 20251022, para que den lo mismo cada vez que se corran. Las secciones A, B y C de esta hoja se recalculan solas dentro del Excel, y ese mismo script las vuelve a calcular aparte: las dos vías dan la misma cifra.
A43: E · DÓNDE NO LLEGA EL DATO
A44: EL ASUNTO CON CIFRA. En las tablas por estilo, «Con cifra concreta» abre 41,6 % contra 29,2 % del promedio, y es tentador titular con eso. No se puede, por una razón que hay que decir antes de que la pregunten: son 21 campañas pero UN SOLO asunto, el único del archivo que lleva un número. Con un solo caso no se puede separar «lleva cifra» de «es esa frase», que además dice «Flash Sale», «Ahorra YA» y «tus favoritos». Y el segundo mejor asunto, sin ninguna cifra, abre 40,7 %: nueve décimas de punto menos.
A46: LO MISMO AL REVÉS. «Pregunta abierta» es el estilo que peor abre (15,9 %) y también es un solo asunto. Tampoco se reporta como hallazgo.
A48: QUÉ SE HACE CON ESO. La cifra pasa de recomendación a hipótesis, y la hipótesis se resuelve con el A/B que ya está propuesto: la misma campaña, 10 % de la base por versión, una con la cifra al principio y otra con la cifra al final. Cuesta cero y en una campaña queda medido. El plan que se ejecuta sin esperar nada es el otro: ningún asunto vuelve a abrir con etiqueta.

Sheet TABLERO
A1: Tablero
A2: Los números grandes son el embudo. Los gráficos responden, en orden: ¿qué impulsa los resultados? ¿qué no? ¿y los ingresos?
A4: Campañas analizadas | C4: Emails enviados | E4: Tasa de apertura | G4: CTR | I4: CTOR | K4: Brecha mejor/peor asunto
A5: 489 | C5: 120096662 | E5: 28.944019 | G5: 9.7276675 | I5: 33.608558 | K5: 3.8810091
A6: de 576 en el archivo | C6: en los tres meses | E6: promedio ponderado | G6: clics sobre envíos | I6: clics sobre aperturas | K6: la palanca real
A54: CÓMO LEER ESTOS CUATRO GRÁFICOS
A55: Arriba a la izquierda | C55: Cada barra es un asunto. El mejor logra 41,6 % de apertura y el peor 10,7 %: casi cuatro veces de diferencia con la misma base de datos y la misma marca.
A56: Arriba a la derecha | C56: Mide cuánto explica cada factor. El asunto explica el 47 % de la variación. El tipo de campaña, la hora, el día y el mes explican entre 0 y 1,4 %, que es decir nada.
A57: Abajo a la izquierda | C57: Agosto, septiembre y octubre son prácticamente idénticos. No hay estacionalidad que aprovechar en esta ventana.
A58: Abajo a la derecha | C58: Si los ingresos dependieran de los clics, esta nube sería una diagonal. Es una mancha. Eso apunta a un problema de medición, no a un hallazgo de negocio.

Sheet HALLAZGOS
A1: Hallazgos · qué se probó y qué resultó
A2: Todas las hipótesis que se probaron, en una lista. Cada una tiene su tabla y su gráfica en las hojas H1 a H4. "p" es la probabilidad de ver la diferencia por azar: por debajo de 0,05 se considera real.
A4: # | B4: Hipótesis | C4: Métrica | D4: p | E4: ¿Cambia el resultado? | F4: Dónde ver la gráfica
A5: H1 | B5: ¿El mes cambia cuántas personas abren? | C5: Apertura | D5: 0,823 | E5: No | F5: =HYPERLINK("#'H1 CALENDARIO'!A5","H1 CALENDARIO") -> H1 CALENDARIO
A6: H2 | B6: ¿El día de la semana cambia cuántas personas abren? | C6: Apertura | D6: 0,860 | E6: No | F6: =HYPERLINK("#'H1 CALENDARIO'!A29","H1 CALENDARIO") -> H1 CALENDARIO
A7: H3 | B7: ¿La hora de envío cambia cuántas personas abren? | C7: Apertura | D7: 0,750 | E7: No | F7: =HYPERLINK("#'H1 CALENDARIO'!A53","H1 CALENDARIO") -> H1 CALENDARIO
A8: H4 | B8: ¿Las fechas de pago (quincena) cambian cuántas personas abren? | C8: Apertura | D8: 0,659 | E8: No | F8: =HYPERLINK("#'H1 CALENDARIO'!A77","H1 CALENDARIO") -> H1 CALENDARIO
A9: H5 | B9: ¿Las fechas de Colombia cambian cuántas personas abren? | C9: Apertura | D9: — | E9: No | F9: =HYPERLINK("#'H1 CALENDARIO'!A101","H1 CALENDARIO") -> H1 CALENDARIO
A10: H6 | B10: ¿Los días con muchos envíos (20 o más campañas) abren menos? | C10: Apertura | D10: 0,373 | E10: No | F10: =HYPERLINK("#'H1 CALENDARIO'!A125","H1 CALENDARIO") -> H1 CALENDARIO
A11: H7 | B11: ¿Hay algún día o semana que se salga de lo normal? | C11: Apertura | D11: — | E11: No | F11: =HYPERLINK("#'H1 CALENDARIO'!A149","H1 CALENDARIO") -> H1 CALENDARIO
A12: H8 | B12: ¿El tipo de campaña cambia cuántas personas abren? | C12: Apertura | D12: 0,211 | E12: No | F12: =HYPERLINK("#'H2 CAMPAÑA'!A5","H2 CAMPAÑA") -> H2 CAMPAÑA
A13: H9 | B13: ¿El objetivo de la campaña (vender, educar, lanzar, fidelizar) cambia el resultado? | C13: Apertura | D13: 0,357 | E13: No | F13: =HYPERLINK("#'H2 CAMPAÑA'!A29","H2 CAMPAÑA") -> H2 CAMPAÑA
A14: H10 | B14: ¿El tamaño del envío cambia cuántas personas abren? | C14: Apertura | D14: 0,832 | E14: No | F14: =HYPERLINK("#'H2 CAMPAÑA'!A53","H2 CAMPAÑA") -> H2 CAMPAÑA
A15: H11 | B15: ¿Repetir el mismo asunto lo desgasta? | C15: Apertura | D15: 0,449 | E15: No | F15: =HYPERLINK("#'H2 CAMPAÑA'!A77","H2 CAMPAÑA") -> H2 CAMPAÑA
A16: H12 | B16: ¿Los ingresos y la conversión suben con los clics? | C16: Ingresos | D16: 0,406 | E16: No | F16: =HYPERLINK("#'H2 CAMPAÑA'!A101","H2 CAMPAÑA") -> H2 CAMPAÑA
A17: H13 | B17: ¿Qué explica más la apertura? | C17: Apertura | D17: < 0,001 | E17: Sí | F17: =HYPERLINK("#'H3 ASUNTO'!A5","H3 ASUNTO") -> H3 ASUNTO
A18: H14 | B18: ¿El efecto del asunto es real o es suerte? | C18: Apertura | D18: — | E18: Sí | F18: =HYPERLINK("#'H3 ASUNTO'!A29","H3 ASUNTO") -> H3 ASUNTO
A19: H15 | B19: ¿Qué estilo de asunto abre más: con cifra, recompensa, solo urgencia o pregunta? | C19: Apertura | D19: < 0,001 | E19: Sí | F19: =HYPERLINK("#'H3 ASUNTO'!A53","H3 ASUNTO") -> H3 ASUNTO
A20: H16 | B20: ¿Empezar el asunto con una etiqueta ("Actualización", "Presentamos", "Oportunidades") resta? | C20: Apertura | D20: < 0,001 | E20: Sí | F20: =HYPERLINK("#'H3 ASUNTO'!A77","H3 ASUNTO") -> H3 ASUNTO
A21: H17 | B21: ¿Un preheader vago resta? | C21: Apertura | D21: < 0,001 | E21: Sí | F21: =HYPERLINK("#'H3 ASUNTO'!A101","H3 ASUNTO") -> H3 ASUNTO
A22: H18 | B22: ¿Se ve en ejemplos concretos? | C22: Apertura | D22: — | E22: Sí | F22: =HYPERLINK("#'H3 ASUNTO'!A125","H3 ASUNTO") -> H3 ASUNTO
A23: H19 | B23: ¿Los asuntos que se abren también reciben clics? | C23: CTR | D23: < 0,001 | E23: Sí | F23: =HYPERLINK("#'H3 ASUNTO'!A149","H3 ASUNTO") -> H3 ASUNTO
A24: H20 | B24: ¿Cumplir las buenas prácticas de Mailchimp (máximo 60 caracteres, 9 palabras, 3 signos y 1 emoji) sube la apertura? | C24: Apertura | D24: 0,525 | E24: No | F24: =HYPERLINK("#'H3 ASUNTO'!A173","H3 ASUNTO") -> H3 ASUNTO
A25: H21 | B25: En las campañas de descuento, ¿qué tipo de campaña funciona mejor? | C25: Apertura | D25: 0,002 | E25: Sí | F25: =HYPERLINK("#'H4 TEMÁTICA HOT SALE'!A8","H4 TEMÁTICA HOT SALE") -> H4 TEMÁTICA HOT SALE
A26: H22 | B26: En las campañas de descuento, ¿qué estilo de asunto funciona? | C26: Apertura | D26: < 0,001 | E26: Sí | F26: =HYPERLINK("#'H4 TEMÁTICA HOT SALE'!A32","H4 TEMÁTICA HOT SALE") -> H4 TEMÁTICA HOT SALE
A27: H23 | B27: En las campañas de descuento, ¿importan las fechas de pago (quincena)? | C27: Apertura | D27: 0,613 | E27: No | F27: =HYPERLINK("#'H4 TEMÁTICA HOT SALE'!A56","H4 TEMÁTICA HOT SALE") -> H4 TEMÁTICA HOT SALE
A28: H24 | B28: En las campañas de descuento, ¿importa el día de la semana? | C28: Apertura | D28: 0,474 | E28: No | F28: =HYPERLINK("#'H4 TEMÁTICA HOT SALE'!A80","H4 TEMÁTICA HOT SALE") -> H4 TEMÁTICA HOT SALE
A29: H25 | B29: En las campañas de descuento, ¿importa la hora de envío? | C29: Apertura | D29: 0,155 | E29: No | F29: =HYPERLINK("#'H4 TEMÁTICA HOT SALE'!A104","H4 TEMÁTICA HOT SALE") -> H4 TEMÁTICA HOT SALE
A30: H26 | B30: ¿Poner el límite de tiempo en el asunto ("solo por hoy", "últimas horas") ayuda? | C30: Apertura | D30: 0,003 | E30: Sí | F30: =HYPERLINK("#'H4 TEMÁTICA HOT SALE'!A128","H4 TEMÁTICA HOT SALE") -> H4 TEMÁTICA HOT SALE
A31: H27 | B31: ¿La urgencia funciona si va con un beneficio concreto? | C31: Apertura | D31: — | E31: Señal | F31: =HYPERLINK("#'H4 TEMÁTICA HOT SALE'!A152","H4 TEMÁTICA HOT SALE") -> H4 TEMÁTICA HOT SALE
A32: H28 | B32: Dentro de Flash Sale, ¿cuánto pesa el asunto? | C32: Apertura | D32: < 0,001 | E32: Sí | F32: =HYPERLINK("#'H4 TEMÁTICA HOT SALE'!A176","H4 TEMÁTICA HOT SALE") -> H4 TEMÁTICA HOT SALE
A33: H29 | B33: Los Hot Sale anteriores, ¿funcionaron? | C33: Apertura | D33: 0,022 | E33: Sí | F33: =HYPERLINK("#'H4 TEMÁTICA HOT SALE'!A210","H4 TEMÁTICA HOT SALE") -> H4 TEMÁTICA HOT SALE
A34: H30 | B34: ¿Qué pasó campaña por campaña en los Hot Sale anteriores? | C34: Apertura | D34: — | E34: Señal | F34: =HYPERLINK("#'H4 TEMÁTICA HOT SALE'!A234","H4 TEMÁTICA HOT SALE") -> H4 TEMÁTICA HOT SALE
A36: Cómo leer "¿Cambia el resultado?": Sí = la diferencia es real. No = puede ser azar. Señal = va en la dirección esperada pero hay pocos casos; se confirma con el A/B del Hot Sale.

Sheet H0 DATOS
A1: Antes de analizar · qué datos se usan y por qué se excluye el 15 %
A2: Las 576 filas del archivo, cuántas se usan y por qué se dejó cada una fuera. El detalle fila por fila está en FILAS EXCLUIDAS.
A4: Se analiza el 85 % del archivo: 489 de 576 filas
A5: Filas | B5: Filas | C5: % del archivo
A6: Se analizan | B6: =COUNT('DATOS LIMPIOS'!$G$5:$G$493) -> 489 | C6: =B6/B8*100 -> 84.895833
A7: Se excluyen | B7: =COUNTA('FILAS EXCLUIDAS'!$C$5:$C$200) -> 87 | C7: =B7/B8*100 -> 15.104167
A8: Total del archivo | B8: =B6+B7 -> 576 | C8: =B8/B8*100 -> 100
A18: Por qué se excluye cada fila: la mayoría tiene más clics que aperturas
A19: Motivo | B19: Filas | C19: Qué significa
A20: Imposible: más clics que aperturas | B20: =COUNTIF('FILAS EXCLUIDAS'!$C$5:$C$200,A20) -> 72 | C20: Más clics que personas que abrieron. Puede pasar si la columna cuenta clics repetidos de una misma persona, por eso se revisó todo con y sin ellas.
A21: Fecha fuera de la ventana ago-oct 2025 | B21: =COUNTIF('FILAS EXCLUIDAS'!$C$5:$C$200,A21) -> 7 | C21: Fechas de 1990, 2022 y 2026. El caso pide los últimos tres meses.
A22: Imposible: más aperturas que envíos | B22: =COUNTIF('FILAS EXCLUIDAS'!$C$5:$C$200,A22) -> 5 | C22: No puede abrir más gente de la que recibió el correo.
A23: Campos vacíos en métricas de cálculo | B23: =COUNTIF('FILAS EXCLUIDAS'!$C$5:$C$200,A23) -> 3 | C23: Sin envíos, aperturas o clics no se puede calcular ninguna tasa.
A25: Las ventas no se excluyen, pero tampoco se usan: conversión, ingresos y bajas se comportan como números al azar (hoja H2 CAMPAÑA). Por eso todo el análisis se mide en aperturas y clics.

Sheet H1 CALENDARIO
A1: Hipótesis de calendario · ¿cuándo se envía importa?
A2: Cada bloque es una hipótesis: la pregunta, la respuesta, la tabla (fórmulas sobre DATOS LIMPIOS) y su gráfica. "p" es la probabilidad de ver la diferencia por azar.
A4: H1 · ¿El mes cambia cuántas personas abren?
A5: No. Agosto, septiembre y octubre abren prácticamente igual. No hay estacionalidad que aprovechar en esta ventana.
A8: Tabla H1 · Apertura y CTR por mes de envío
A9: Mes | B9: Campañas | C9: Apertura (%) | D9: CTR (%) | E9: Promedio general de apertura (%)
A10: Agosto | B10: =COUNTIFS('DATOS LIMPIOS'!$T$5:$T$493,"Agosto") -> 159 | C10: =AVERAGEIFS('DATOS LIMPIOS'!$M$5:$M$493,'DATOS LIMPIOS'!$T$5:$T$493,"Agosto") -> 29.514345 | D10: =AVERAGEIFS('DATOS LIMPIOS'!$N$5:$N$493,'DATOS LIMPIOS'!$T$5:$T$493,"Agosto") -> 10.016983 | E10: =AVERAGE('DATOS LIMPIOS'!$M$5:$M$493) -> 29.186614
A11: Septiembre | B11: =COUNTIFS('DATOS LIMPIOS'!$T$5:$T$493,"Septiembre") -> 167 | C11: =AVERAGEIFS('DATOS LIMPIOS'!$M$5:$M$493,'DATOS LIMPIOS'!$T$5:$T$493,"Septiembre") -> 28.665371 | D11: =AVERAGEIFS('DATOS LIMPIOS'!$N$5:$N$493,'DATOS LIMPIOS'!$T$5:$T$493,"Septiembre") -> 9.6054365 | E11: =AVERAGE('DATOS LIMPIOS'!$M$5:$M$493) -> 29.186614
A12: Octubre | B12: =COUNTIFS('DATOS LIMPIOS'!$T$5:$T$493,"Octubre") -> 163 | C12: =AVERAGEIFS('DATOS LIMPIOS'!$M$5:$M$493,'DATOS LIMPIOS'!$T$5:$T$493,"Octubre") -> 29.400958 | D12: =AVERAGEIFS('DATOS LIMPIOS'!$N$5:$N$493,'DATOS LIMPIOS'!$T$5:$T$493,"Octubre") -> 9.7492145 | E12: =AVERAGE('DATOS LIMPIOS'!$M$5:$M$493) -> 29.186614
A14: ¿Cambia el resultado? No | D14: p = 0,823 (calculado en Python)
A28: H2 · ¿El día de la semana cambia cuántas personas abren?
A29: No. Todos los días quedan cerca del promedio. El domingo se ve más alto, pero son muy pocas campañas: con tan pocas, el promedio se mueve por azar.
A32: Tabla H2 · Apertura y CTR por día de la semana
A33: Día | B33: Campañas | C33: Apertura (%) | D33: CTR (%) | E33: Promedio general de apertura (%)
A34: Lunes | B34: =COUNTIFS('DATOS LIMPIOS'!$U$5:$U$493,"Lunes") -> 115 | C34: =AVERAGEIFS('DATOS LIMPIOS'!$M$5:$M$493,'DATOS LIMPIOS'!$U$5:$U$493,"Lunes") -> 29.509194 | D34: =AVERAGEIFS('DATOS LIMPIOS'!$N$5:$N$493,'DATOS LIMPIOS'!$U$5:$U$493,"Lunes") -> 9.9843773 | E34: =AVERAGE('DATOS LIMPIOS'!$M$5:$M$493) -> 29.186614
A35: Martes | B35: =COUNTIFS('DATOS LIMPIOS'!$U$5:$U$493,"Martes") -> 93 | C35: =AVERAGEIFS('DATOS LIMPIOS'!$M$5:$M$493,'DATOS LIMPIOS'!$U$5:$U$493,"Martes") -> 28.853982 | D35: =AVERAGEIFS('DATOS LIMPIOS'!$N$5:$N$493,'DATOS LIMPIOS'!$U$5:$U$493,"Martes") -> 10.172968 | E35: =AVERAGE('DATOS LIMPIOS'!$M$5:$M$493) -> 29.186614
A36: Miércoles | B36: =COUNTIFS('DATOS LIMPIOS'!$U$5:$U$493,"Miércoles") -> 98 | C36: =AVERAGEIFS('DATOS LIMPIOS'!$M$5:$M$493,'DATOS LIMPIOS'!$U$5:$U$493,"Miércoles") -> 29.805531 | D36: =AVERAGEIFS('DATOS LIMPIOS'!$N$5:$N$493,'DATOS LIMPIOS'!$U$5:$U$493,"Miércoles") -> 9.9605132 | E36: =AVERAGE('DATOS LIMPIOS'!$M$5:$M$493) -> 29.186614
A37: Jueves | B37: =COUNTIFS('DATOS LIMPIOS'!$U$5:$U$493,"Jueves") -> 62 | C37: =AVERAGEIFS('DATOS LIMPIOS'!$M$5:$M$493,'DATOS LIMPIOS'!$U$5:$U$493,"Jueves") -> 28.922959 | D37: =AVERAGEIFS('DATOS LIMPIOS'!$N$5:$N$493,'DATOS LIMPIOS'!$U$5:$U$493,"Jueves") -> 8.6545725 | E37: =AVERAGE('DATOS LIMPIOS'!$M$5:$M$493) -> 29.186614
A38: Viernes | B38: =COUNTIFS('DATOS LIMPIOS'!$U$5:$U$493,"Viernes") -> 46 | C38: =AVERAGEIFS('DATOS LIMPIOS'!$M$5:$M$493,'DATOS LIMPIOS'!$U$5:$U$493,"Viernes") -> 27.798718 | D38: =AVERAGEIFS('DATOS LIMPIOS'!$N$5:$N$493,'DATOS LIMPIOS'!$U$5:$U$493,"Viernes") -> 9.4066366 | E38: =AVERAGE('DATOS LIMPIOS'!$M$5:$M$493) -> 29.186614
A39: Sábado | B39: =COUNTIFS('DATOS LIMPIOS'!$U$5:$U$493,"Sábado") -> 64 | C39: =AVERAGEIFS('DATOS LIMPIOS'!$M$5:$M$493,'DATOS LIMPIOS'!$U$5:$U$493,"Sábado") -> 28.625989 | D39: =AVERAGEIFS('DATOS LIMPIOS'!$N$5:$N$493,'DATOS LIMPIOS'!$U$5:$U$493,"Sábado") -> 9.6393947 | E39: =AVERAGE('DATOS LIMPIOS'!$M$5:$M$493) -> 29.186614
A40: Domingo | B40: =COUNTIFS('DATOS LIMPIOS'!$U$5:$U$493,"Domingo") -> 11 | C40: =AVERAGEIFS('DATOS LIMPIOS'!$M$5:$M$493,'DATOS LIMPIOS'!$U$5:$U$493,"Domingo") -> 33.664234 | D40: =AVERAGEIFS('DATOS LIMPIOS'!$N$5:$N$493,'DATOS LIMPIOS'!$U$5:$U$493,"Domingo") -> 11.75458 | E40: =AVERAGE('DATOS LIMPIOS'!$M$5:$M$493) -> 29.186614
A42: ¿Cambia el resultado? No | D42: p = 0,860 (calculado en Python)
A52: H3 · ¿La hora de envío cambia cuántas personas abren?
A53: No. Ninguna hora se separa del promedio de forma real.
A56: Tabla H3 · Apertura y CTR por hora de envío
A57: Hora | B57: Campañas | C57: Apertura (%) | D57: CTR (%) | E57: Promedio general de apertura (%)
A58: 8 | B58: =COUNTIFS('DATOS LIMPIOS'!$V$5:$V$493,8) -> 31 | C58: =AVERAGEIFS('DATOS LIMPIOS'!$M$5:$M$493,'DATOS LIMPIOS'!$V$5:$V$493,8) -> 28.287787 | D58: =AVERAGEIFS('DATOS LIMPIOS'!$N$5:$N$493,'DATOS LIMPIOS'!$V$5:$V$493,8) -> 8.2129061 | E58: =AVERAGE('DATOS LIMPIOS'!$M$5:$M$493) -> 29.186614
A59: 9 | B59: =COUNTIFS('DATOS LIMPIOS'!$V$5:$V$493,9) -> 36 | C59: =AVERAGEIFS('DATOS LIMPIOS'!$M$5:$M$493,'DATOS LIMPIOS'!$V$5:$V$493,9) -> 28.997432 | D59: =AVERAGEIFS('DATOS LIMPIOS'!$N$5:$N$493,'DATOS LIMPIOS'!$V$5:$V$493,9) -> 9.6156747 | E59: =AVERAGE('DATOS LIMPIOS'!$M$5:$M$493) -> 29.186614
A60: 10 | B60: =COUNTIFS('DATOS LIMPIOS'!$V$5:$V$493,10) -> 97 | C60: =AVERAGEIFS('DATOS LIMPIOS'!$M$5:$M$493,'DATOS LIMPIOS'!$V$5:$V$493,10) -> 28.945982 | D60: =AVERAGEIFS('DATOS LIMPIOS'!$N$5:$N$493,'DATOS LIMPIOS'!$V$5:$V$493,10) -> 10.274592 | E60: =AVERAGE('DATOS LIMPIOS'!$M$5:$M$493) -> 29.186614
A61: 11 | B61: =COUNTIFS('DATOS LIMPIOS'!$V$5:$V$493,11) -> 89 | C61: =AVERAGEIFS('DATOS LIMPIOS'!$M$5:$M$493,'DATOS LIMPIOS'!$V$5:$V$493,11) -> 28.113088 | D61: =AVERAGEIFS('DATOS LIMPIOS'!$N$5:$N$493,'DATOS LIMPIOS'!$V$5:$V$493,11) -> 9.5593715 | E61: =AVERAGE('DATOS LIMPIOS'!$M$5:$M$493) -> 29.186614
A62: 12 | B62: =COUNTIFS('DATOS LIMPIOS'!$V$5:$V$493,12) -> 30 | C62: =AVERAGEIFS('DATOS LIMPIOS'!$M$5:$M$493,'DATOS LIMPIOS'!$V$5:$V$493,12) -> 32.530275 | D62: =AVERAGEIFS('DATOS LIMPIOS'!$N$5:$N$493,'DATOS LIMPIOS'!$V$5:$V$493,12) -> 9.7455376 | E62: =AVERAGE('DATOS LIMPIOS'!$M$5:$M$493) -> 29.186614
A63: 13 | B63: =COUNTIFS('DATOS LIMPIOS'!$V$5:$V$493,13) -> 69 | C63: =AVERAGEIFS('DATOS LIMPIOS'!$M$5:$M$493,'DATOS LIMPIOS'!$V$5:$V$493,13) -> 28.707113 | D63: =AVERAGEIFS('DATOS LIMPIOS'!$N$5:$N$493,'DATOS LIMPIOS'!$V$5:$V$493,13) -> 9.5853681 | E63: =AVERAGE('DATOS LIMPIOS'!$M$5:$M$493) -> 29.186614
A64: 14 | B64: =COUNTIFS('DATOS LIMPIOS'!$V$5:$V$493,14) -> 37 | C64: =AVERAGEIFS('DATOS LIMPIOS'!$M$5:$M$493,'DATOS LIMPIOS'!$V$5:$V$493,14) -> 27.847081 | D64: =AVERAGEIFS('DATOS LIMPIOS'!$N$5:$N$493,'DATOS LIMPIOS'!$V$5:$V$493,14) -> 9.810471 | E64: =AVERAGE('DATOS LIMPIOS'!$M$5:$M$493) -> 29.186614
A65: 15 | B65: =COUNTIFS('DATOS LIMPIOS'!$V$5:$V$493,15) -> 65 | C65: =AVERAGEIFS('DATOS LIMPIOS'!$M$5:$M$493,'DATOS LIMPIOS'!$V$5:$V$493,15) -> 31.017355 | D65: =AVERAGEIFS('DATOS LIMPIOS'!$N$5:$N$493,'DATOS LIMPIOS'!$V$5:$V$493,15) -> 10.467229 | E65: =AVERAGE('DATOS LIMPIOS'!$M$5:$M$493) -> 29.186614
A66: 16 | B66: =COUNTIFS('DATOS LIMPIOS'!$V$5:$V$493,16) -> 35 | C66: =AVERAGEIFS('DATOS LIMPIOS'!$M$5:$M$493,'DATOS LIMPIOS'!$V$5:$V$493,16) -> 29.669457 | D66: =AVERAGEIFS('DATOS LIMPIOS'!$N$5:$N$493,'DATOS LIMPIOS'!$V$5:$V$493,16) -> 9.7323544 | E66: =AVERAGE('DATOS LIMPIOS'!$M$5:$M$493) -> 29.186614
A68: ¿Cambia el resultado? No | D68: p = 0,750 (calculado en Python)
A76: H4 · ¿Las fechas de pago (quincena) cambian cuántas personas abren?
A77: No en aperturas. En clics, la quincena sale un poco más baja, pero va al revés de lo esperado y no es estable: se cae al mover un día la definición. Se toma como ruido.
A80: Tabla H4 · Apertura y CTR según el momento del mes (fechas de pago)
A81: Momento del mes | B81: Campañas | C81: Apertura (%) | D81: CTR (%) | E81: Promedio general de apertura (%)
...

Sheet H2 CAMPAÑA
A1: Hipótesis de campaña · ¿el tipo, el objetivo o el tamaño importan?
A2: Mismo formato: pregunta, respuesta, tabla con fórmulas y gráfica.
A4: H8 · ¿El tipo de campaña cambia cuántas personas abren?
A5: No. Flash Sale, Newsletter, lanzamientos y los demás abren parecido. Lo que cambia es el asunto dentro de cada tipo (hoja H3).
A8: Tabla H8 · Apertura y CTR por tipo de campaña
A9: Tipo de campaña | B9: Campañas | C9: Apertura (%) | D9: CTR (%) | E9: Promedio general de apertura (%)
A10: Customer Appreciation | B10: =COUNTIF('DATOS LIMPIOS'!$B$5:$B$493,"Customer Appreciation") -> 73 | C10: =AVERAGEIF('DATOS LIMPIOS'!$B$5:$B$493,"Customer Appreciation",'DATOS LIMPIOS'!$M$5:$M$493) -> 31.113651 | D10: =AVERAGEIF('DATOS LIMPIOS'!$B$5:$B$493,"Customer Appreciation",'DATOS LIMPIOS'!$N$5:$N$493) -> 9.9969928 | E10: =AVERAGE('DATOS LIMPIOS'!$M$5:$M$493) -> 29.186614
A11: Exclusive Offers | B11: =COUNTIF('DATOS LIMPIOS'!$B$5:$B$493,"Exclusive Offers") -> 79 | C11: =AVERAGEIF('DATOS LIMPIOS'!$B$5:$B$493,"Exclusive Offers",'DATOS LIMPIOS'!$M$5:$M$493) -> 27.021448 | D11: =AVERAGEIF('DATOS LIMPIOS'!$B$5:$B$493,"Exclusive Offers",'DATOS LIMPIOS'!$N$5:$N$493) -> 9.2971825 | E11: =AVERAGE('DATOS LIMPIOS'!$M$5:$M$493) -> 29.186614
A12: Flash Sale | B12: =COUNTIF('DATOS LIMPIOS'!$B$5:$B$493,"Flash Sale") -> 81 | C12: =AVERAGEIF('DATOS LIMPIOS'!$B$5:$B$493,"Flash Sale",'DATOS LIMPIOS'!$M$5:$M$493) -> 29.440902 | D12: =AVERAGEIF('DATOS LIMPIOS'!$B$5:$B$493,"Flash Sale",'DATOS LIMPIOS'!$N$5:$N$493) -> 9.205166 | E12: =AVERAGE('DATOS LIMPIOS'!$M$5:$M$493) -> 29.186614
A13: Holiday Discounts | B13: =COUNTIF('DATOS LIMPIOS'!$B$5:$B$493,"Holiday Discounts") -> 79 | C13: =AVERAGEIF('DATOS LIMPIOS'!$B$5:$B$493,"Holiday Discounts",'DATOS LIMPIOS'!$M$5:$M$493) -> 30.711144 | D13: =AVERAGEIF('DATOS LIMPIOS'!$B$5:$B$493,"Holiday Discounts",'DATOS LIMPIOS'!$N$5:$N$493) -> 9.055774 | E13: =AVERAGE('DATOS LIMPIOS'!$M$5:$M$493) -> 29.186614
A14: New Product Launch | B14: =COUNTIF('DATOS LIMPIOS'!$B$5:$B$493,"New Product Launch") -> 84 | C14: =AVERAGEIF('DATOS LIMPIOS'!$B$5:$B$493,"New Product Launch",'DATOS LIMPIOS'!$M$5:$M$493) -> 29.458248 | D14: =AVERAGEIF('DATOS LIMPIOS'!$B$5:$B$493,"New Product Launch",'DATOS LIMPIOS'!$N$5:$N$493) -> 10.443531 | E14: =AVERAGE('DATOS LIMPIOS'!$M$5:$M$493) -> 29.186614
A15: Newsletter | B15: =COUNTIF('DATOS LIMPIOS'!$B$5:$B$493,"Newsletter") -> 93 | C15: =AVERAGEIF('DATOS LIMPIOS'!$B$5:$B$493,"Newsletter",'DATOS LIMPIOS'!$M$5:$M$493) -> 27.751365 | D15: =AVERAGEIF('DATOS LIMPIOS'!$B$5:$B$493,"Newsletter",'DATOS LIMPIOS'!$N$5:$N$493) -> 10.574097 | E15: =AVERAGE('DATOS LIMPIOS'!$M$5:$M$493) -> 29.186614
A17: ¿Cambia el resultado? No | D17: p = 0,211 (calculado en Python)
A28: H9 · ¿El objetivo de la campaña (vender, educar, lanzar, fidelizar) cambia el resultado?
A29: No. Los cuatro objetivos abren y clican parecido.
A32: Tabla H9 · Apertura y CTR por objetivo de la campaña
A33: Objetivo | B33: Campañas | C33: Apertura (%) | D33: CTR (%) | E33: Promedio general de apertura (%)
A34: Vender | B34: =COUNTIFS('DATOS LIMPIOS'!$Z$5:$Z$493,"Vender") -> 239 | C34: =AVERAGEIFS('DATOS LIMPIOS'!$M$5:$M$493,'DATOS LIMPIOS'!$Z$5:$Z$493,"Vender") -> 29.061037 | D34: =AVERAGEIFS('DATOS LIMPIOS'!$N$5:$N$493,'DATOS LIMPIOS'!$Z$5:$Z$493,"Vender") -> 9.1862009 | E34: =AVERAGE('DATOS LIMPIOS'!$M$5:$M$493) -> 29.186614
A35: Educar | B35: =COUNTIFS('DATOS LIMPIOS'!$Z$5:$Z$493,"Educar") -> 93 | C35: =AVERAGEIFS('DATOS LIMPIOS'!$M$5:$M$493,'DATOS LIMPIOS'!$Z$5:$Z$493,"Educar") -> 27.751365 | D35: =AVERAGEIFS('DATOS LIMPIOS'!$N$5:$N$493,'DATOS LIMPIOS'!$Z$5:$Z$493,"Educar") -> 10.574097 | E35: =AVERAGE('DATOS LIMPIOS'!$M$5:$M$493) -> 29.186614
A36: Lanzar | B36: =COUNTIFS('DATOS LIMPIOS'!$Z$5:$Z$493,"Lanzar") -> 84 | C36: =AVERAGEIFS('DATOS LIMPIOS'!$M$5:$M$493,'DATOS LIMPIOS'!$Z$5:$Z$493,"Lanzar") -> 29.458248 | D36: =AVERAGEIFS('DATOS LIMPIOS'!$N$5:$N$493,'DATOS LIMPIOS'!$Z$5:$Z$493,"Lanzar") -> 10.443531 | E36: =AVERAGE('DATOS LIMPIOS'!$M$5:$M$493) -> 29.186614
A37: Fidelizar | B37: =COUNTIFS('DATOS LIMPIOS'!$Z$5:$Z$493,"Fidelizar") -> 73 | C37: =AVERAGEIFS('DATOS LIMPIOS'!$M$5:$M$493,'DATOS LIMPIOS'!$Z$5:$Z$493,"Fidelizar") -> 31.113651 | D37: =AVERAGEIFS('DATOS LIMPIOS'!$N$5:$N$493,'DATOS LIMPIOS'!$Z$5:$Z$493,"Fidelizar") -> 9.9969928 | E37: =AVERAGE('DATOS LIMPIOS'!$M$5:$M$493) -> 29.186614
A39: ¿Cambia el resultado? No | D39: p = 0,357 (calculado en Python)
A52: H10 · ¿El tamaño del envío cambia cuántas personas abren?
A53: No. Las campañas pequeñas y las grandes abren casi igual.
A56: Tabla H10 · Apertura y CTR según el tamaño del envío
A57: Tamaño del envío | B57: Campañas | C57: Apertura (%) | D57: CTR (%) | E57: Promedio general de apertura (%)
A58: Menos de 100 mil | B58: =COUNTIFS('DATOS LIMPIOS'!$AA$5:$AA$493,"Menos de 100 mil") -> 98 | C58: =AVERAGEIFS('DATOS LIMPIOS'!$M$5:$M$493,'DATOS LIMPIOS'!$AA$5:$AA$493,"Menos de 100 mil") -> 29.980769 | D58: =AVERAGEIFS('DATOS LIMPIOS'!$N$5:$N$493,'DATOS LIMPIOS'!$AA$5:$AA$493,"Menos de 100 mil") -> 9.9605207 | E58: =AVERAGE('DATOS LIMPIOS'!$M$5:$M$493) -> 29.186614
A59: 100 a 200 mil | B59: =COUNTIFS('DATOS LIMPIOS'!$AA$5:$AA$493,"100 a 200 mil") -> 107 | C59: =AVERAGEIFS('DATOS LIMPIOS'!$M$5:$M$493,'DATOS LIMPIOS'!$AA$5:$AA$493,"100 a 200 mil") -> 29.609856 | D59: =AVERAGEIFS('DATOS LIMPIOS'!$N$5:$N$493,'DATOS LIMPIOS'!$AA$5:$AA$493,"100 a 200 mil") -> 9.6964825 | E59: =AVERAGE('DATOS LIMPIOS'!$M$5:$M$493) -> 29.186614
A60: 200 a 300 mil | B60: =COUNTIFS('DATOS LIMPIOS'!$AA$5:$AA$493,"200 a 300 mil") -> 90 | C60: =AVERAGEIFS('DATOS LIMPIOS'!$M$5:$M$493,'DATOS LIMPIOS'!$AA$5:$AA$493,"200 a 300 mil") -> 28.062716 | D60: =AVERAGEIFS('DATOS LIMPIOS'!$N$5:$N$493,'DATOS LIMPIOS'!$AA$5:$AA$493,"200 a 300 mil") -> 10.01458 | E60: =AVERAGE('DATOS LIMPIOS'!$M$5:$M$493) -> 29.186614
A61: 300 a 400 mil | B61: =COUNTIFS('DATOS LIMPIOS'!$AA$5:$AA$493,"300 a 400 mil") -> 100 | C61: =AVERAGEIFS('DATOS LIMPIOS'!$M$5:$M$493,'DATOS LIMPIOS'!$AA$5:$AA$493,"300 a 400 mil") -> 28.693134 | D61: =AVERAGEIFS('DATOS LIMPIOS'!$N$5:$N$493,'DATOS LIMPIOS'!$AA$5:$AA$493,"300 a 400 mil") -> 9.6839603 | E61: =AVERAGE('DATOS LIMPIOS'!$M$5:$M$493) -> 29.186614
A62: Más de 400 mil | B62: =COUNTIFS('DATOS LIMPIOS'!$AA$5:$AA$493,"Más de 400 mil") -> 94 | C62: =AVERAGEIFS('DATOS LIMPIOS'!$M$5:$M$493,'DATOS LIMPIOS'!$AA$5:$AA$493,"Más de 400 mil") -> 29.477939 | D62: =AVERAGEIFS('DATOS LIMPIOS'!$N$5:$N$493,'DATOS LIMPIOS'!$AA$5:$AA$493,"Más de 400 mil") -> 9.6017791 | E62: =AVERAGE('DATOS LIMPIOS'!$M$5:$M$493) -> 29.186614
A64: ¿Cambia el resultado? No | D64: p = 0,832 (calculado en Python)
A76: H11 · ¿Repetir el mismo asunto lo desgasta?
A77: No. En los asuntos usados 8 o más veces, el primer tercio de sus usos y el último abren igual. Repetir un asunto que gana no lo gasta.
A80: Tabla H11 · Apertura y CTR según el momento de uso del asunto (asuntos usados 8 o más veces)
A81: Momento de uso | B81: Campañas | C81: Apertura (%) | D81: CTR (%) | E81: Promedio general de apertura (%)
A82: Primer tercio | B82: =COUNTIFS('DATOS LIMPIOS'!$AD$5:$AD$493,"Primer tercio") -> 122 | C82: =AVERAGEIFS('DATOS LIMPIOS'!$M$5:$M$493,'DATOS LIMPIOS'!$AD$5:$AD$493,"Primer tercio") -> 30.869712 | D82: =AVERAGEIFS('DATOS LIMPIOS'!$N$5:$N$493,'DATOS LIMPIOS'!$AD$5:$AD$493,"Primer tercio") -> 9.9926913 | E82: =AVERAGE('DATOS LIMPIOS'!$M$5:$M$493) -> 29.186614
A83: Medio | B83: =COUNTIFS('DATOS LIMPIOS'!$AD$5:$AD$493,"Medio") -> 129 | C83: =AVERAGEIFS('DATOS LIMPIOS'!$M$5:$M$493,'DATOS LIMPIOS'!$AD$5:$AD$493,"Medio") -> 28.891211 | D83: =AVERAGEIFS('DATOS LIMPIOS'!$N$5:$N$493,'DATOS LIMPIOS'!$AD$5:$AD$493,"Medio") -> 9.4437399 | E83: =AVERAGE('DATOS LIMPIOS'!$M$5:$M$493) -> 29.186614
A84: Último tercio | B84: =COUNTIFS('DATOS LIMPIOS'!$AD$5:$AD$493,"Último tercio") -> 138 | C84: =AVERAGEIFS('DATOS LIMPIOS'!$M$5:$M$493,'DATOS LIMPIOS'!$AD$5:$AD$493,"Último tercio") -> 30.56545 | D84: =AVERAGEIFS('DATOS LIMPIOS'!$N$5:$N$493,'DATOS LIMPIOS'!$AD$5:$AD$493,"Último tercio") -> 10.257871 | E84: =AVERAGE('DATOS LIMPIOS'!$M$5:$M$493) -> 29.186614
A86: ¿Cambia el resultado? No | D86: p = 0,449 (calculado en Python)
...

Sheet H3 ASUNTO
A1: El hallazgo principal · el asunto decide cuántas personas abren
A2: Las pruebas de que el asunto importa, y de cómo es un asunto que gana.
A4: H13 · ¿Qué explica más la apertura?
A5: El asunto explica casi la mitad de por qué unas campañas abren más que otras. El tipo de campaña, la hora, el día y el mes no llegan al 2 % cada uno.
A8: Tabla H13 · Qué parte de la diferencia en apertura explica cada factor
A9: Factor | B9: % que explica
A10: El asunto | B10: =(SUMPRODUCT(('DATOS LIMPIOS'!$M$5:$M$493-AVERAGE('DATOS LIMPIOS'!$M$5:$M$493))^2)-SUMPRODUCT(('DATOS LIMPIOS'!$M$5:$M$493-'DATOS LIMPIOS'!$Q$5:$Q$493)^2))/SUMPRODUCT(('DATOS LIMPIOS'!$M$5:$M$493-AVERAGE('DATOS LIMPIOS'!$M$5:$M$493))^2)*100 -> 47.410372
A11: El tipo de campaña | B11: =(SUMPRODUCT(('DATOS LIMPIOS'!$M$5:$M$493-AVERAGE('DATOS LIMPIOS'!$M$5:$M$493))^2)-SUMPRODUCT(('DATOS LIMPIOS'!$M$5:$M$493-'DATOS LIMPIOS'!$R$5:$R$493)^2))/SUMPRODUCT(('DATOS LIMPIOS'!$M$5:$M$493-AVERAGE('DATOS LIMPIOS'!$M$5:$M$493))^2)*100 -> 1.3828802
A12: La hora | B12: =SUMPRODUCT((AVERAGEIF('DATOS LIMPIOS'!$V$5:$V$493,'DATOS LIMPIOS'!$V$5:$V$493,'DATOS LIMPIOS'!$M$5:$M$493)-AVERAGE('DATOS LIMPIOS'!$M$5:$M$493))^2)/SUMPRODUCT(('DATOS LIMPIOS'!$M$5:$M$493-AVERAGE('DATOS LIMPIOS'!$M$5:$M$493))^2)*100 -> 1.0467798
A13: El día de la semana | B13: =SUMPRODUCT((AVERAGEIF('DATOS LIMPIOS'!$U$5:$U$493,'DATOS LIMPIOS'!$U$5:$U$493,'DATOS LIMPIOS'!$M$5:$M$493)-AVERAGE('DATOS LIMPIOS'!$M$5:$M$493))^2)/SUMPRODUCT(('DATOS LIMPIOS'!$M$5:$M$493-AVERAGE('DATOS LIMPIOS'!$M$5:$M$493))^2)*100 -> 0.52913858
A14: El mes | B14: =SUMPRODUCT((AVERAGEIF('DATOS LIMPIOS'!$T$5:$T$493,'DATOS LIMPIOS'!$T$5:$T$493,'DATOS LIMPIOS'!$M$5:$M$493)-AVERAGE('DATOS LIMPIOS'!$M$5:$M$493))^2)/SUMPRODUCT(('DATOS LIMPIOS'!$M$5:$M$493-AVERAGE('DATOS LIMPIOS'!$M$5:$M$493))^2)*100 -> 0.09407893
A15: El momento del mes | B15: =SUMPRODUCT((AVERAGEIF('DATOS LIMPIOS'!$W$5:$W$493,'DATOS LIMPIOS'!$W$5:$W$493,'DATOS LIMPIOS'!$M$5:$M$493)-AVERAGE('DATOS LIMPIOS'!$M$5:$M$493))^2)/SUMPRODUCT(('DATOS LIMPIOS'!$M$5:$M$493-AVERAGE('DATOS LIMPIOS'!$M$5:$M$493))^2)*100 -> 0.17975665
A17: ¿Cambia el resultado? Sí | D17: p = < 0,001 (calculado en Python)
A28: H14 · ¿El efecto del asunto es real o es suerte?
A29: Es real. Con dos meses se eligieron los 5 asuntos que más abrían y los 5 que menos, y se miró el tercer mes, que no se usó para elegir. Se hizo tres veces, una con cada mes. Si fuera suerte, los grupos se habrían acercado; siguieron igual de separados.
A32: Tabla H14 · Apertura en el mes de prueba de los 5 asuntos que ganaban y los 5 que perdían
A33: Mes de prueba | B33: Los 5 que ganaban | C33: Los 5 que perdían
A34: Prueba en agosto | B34: =SUMIFS(_calculos!$T$4:$T$69,_calculos!$S$4:$S$69,"5 mejores")/SUMIFS(_calculos!$U$4:$U$69,_calculos!$S$4:$S$69,"5 mejores") -> 39.033107 | C34: =SUMIFS(_calculos!$T$4:$T$69,_calculos!$S$4:$S$69,"5 peores")/SUMIFS(_calculos!$U$4:$U$69,_calculos!$S$4:$S$69,"5 peores") -> 20.596391
A35: Prueba en septiembre | B35: =SUMIFS(_calculos!$AB$4:$AB$69,_calculos!$AA$4:$AA$69,"5 mejores")/SUMIFS(_calculos!$AC$4:$AC$69,_calculos!$AA$4:$AA$69,"5 mejores") -> 38.936539 | C35: =SUMIFS(_calculos!$AB$4:$AB$69,_calculos!$AA$4:$AA$69,"5 peores")/SUMIFS(_calculos!$AC$4:$AC$69,_calculos!$AA$4:$AA$69,"5 peores") -> 16.313814
A36: Prueba en octubre | B36: =SUMIFS(_calculos!$AJ$4:$AJ$69,_calculos!$AI$4:$AI$69,"5 mejores")/SUMIFS(_calculos!$AK$4:$AK$69,_calculos!$AI$4:$AI$69,"5 mejores") -> 39.55018 | C36: =SUMIFS(_calculos!$AJ$4:$AJ$69,_calculos!$AI$4:$AI$69,"5 peores")/SUMIFS(_calculos!$AK$4:$AK$69,_calculos!$AI$4:$AI$69,"5 peores") -> 16.525879
A38: ¿Cambia el resultado? Sí
A52: H15 · ¿Qué estilo de asunto abre más: con cifra, recompensa, solo urgencia o pregunta?
A53: El asunto con una cifra concreta ("Hasta 50%") es el que más abre. Los de recompensa o sorpresa quedan en el promedio. Los que solo meten urgencia sin decir qué recibes ("¡Últimas horas!", "Por tiempo limitado") y la pregunta abierta son los que menos abren.
A56: Tabla H15 · Apertura y CTR según el estilo del asunto
A57: Estilo | B57: Campañas | C57: Apertura (%) | D57: CTR (%)
A58: Con cifra concreta | B58: =COUNTIF('DATOS LIMPIOS'!$AT$5:$AT$493,"Con cifra concreta") -> 21 | C58: =AVERAGEIF('DATOS LIMPIOS'!$AT$5:$AT$493,"Con cifra concreta",'DATOS LIMPIOS'!$M$5:$M$493) -> 41.593593 | D58: =AVERAGEIF('DATOS LIMPIOS'!$AT$5:$AT$493,"Con cifra concreta",'DATOS LIMPIOS'!$N$5:$N$493) -> 10.640008
A59: Recompensa o sorpresa | B59: =COUNTIF('DATOS LIMPIOS'!$AT$5:$AT$493,"Recompensa o sorpresa") -> 130 | C59: =AVERAGEIF('DATOS LIMPIOS'!$AT$5:$AT$493,"Recompensa o sorpresa",'DATOS LIMPIOS'!$M$5:$M$493) -> 29.134331 | D59: =AVERAGEIF('DATOS LIMPIOS'!$AT$5:$AT$493,"Recompensa o sorpresa",'DATOS LIMPIOS'!$N$5:$N$493) -> 9.5944867
A60: Otro: beneficio o novedad | B60: =COUNTIF('DATOS LIMPIOS'!$AT$5:$AT$493,"Otro: beneficio o novedad") -> 267 | C60: =AVERAGEIF('DATOS LIMPIOS'!$AT$5:$AT$493,"Otro: beneficio o novedad",'DATOS LIMPIOS'!$M$5:$M$493) -> 30.545098 | D60: =AVERAGEIF('DATOS LIMPIOS'!$AT$5:$AT$493,"Otro: beneficio o novedad",'DATOS LIMPIOS'!$N$5:$N$493) -> 10.270903
A61: Solo urgencia, sin cifra | B61: =COUNTIF('DATOS LIMPIOS'!$AT$5:$AT$493,"Solo urgencia, sin cifra") -> 61 | C61: =AVERAGEIF('DATOS LIMPIOS'!$AT$5:$AT$493,"Solo urgencia, sin cifra",'DATOS LIMPIOS'!$M$5:$M$493) -> 21.257416 | D61: =AVERAGEIF('DATOS LIMPIOS'!$AT$5:$AT$493,"Solo urgencia, sin cifra",'DATOS LIMPIOS'!$N$5:$N$493) -> 8.0652297
A62: Pregunta abierta | B62: =COUNTIF('DATOS LIMPIOS'!$AT$5:$AT$493,"Pregunta abierta") -> 10 | C62: =AVERAGEIF('DATOS LIMPIOS'!$AT$5:$AT$493,"Pregunta abierta",'DATOS LIMPIOS'!$M$5:$M$493) -> 15.908214 | D62: =AVERAGEIF('DATOS LIMPIOS'!$AT$5:$AT$493,"Pregunta abierta",'DATOS LIMPIOS'!$N$5:$N$493) -> 8.089655
A64: ¿Cambia el resultado? Sí | D64: p = < 0,001 (calculado en Python)
A65: Cómo se clasifica (columna AT de DATOS LIMPIOS, en este orden): si tiene un número es "con cifra"; si tiene signo de pregunta, "pregunta"; si tiene palabras de urgencia, "solo urgencia"; si habla de recompensa, regalo o sorpresa, "recompensa". Ojo: "con cifra" es un solo asunto y "pregunta" otro, así que son señales. "Solo urgencia" sí se sostiene comparando asunto por asunto dentro del mismo tipo (p = 0,008).
A76: H16 · ¿Empezar el asunto con una etiqueta ("Actualización", "Presentamos", "Oportunidades") resta?
A77: Sí, y mucho, en los tres meses. Esos asuntos dicen qué tipo de correo es, pero no qué hay adentro. Las palabras que cuentan como etiqueta están en la fórmula de la columna AH de DATOS LIMPIOS.
A80: Tabla H16 · Apertura de asuntos que dicen qué recibes contra los que empiezan con una etiqueta, por mes
A81: Mes | B81: Dice qué recibes | C81: Empieza con etiqueta
A82: Agosto | B82: =AVERAGEIFS('DATOS LIMPIOS'!$M$5:$M$493,'DATOS LIMPIOS'!$T$5:$T$493,"Agosto",'DATOS LIMPIOS'!$AH$5:$AH$493,"No") -> 32.555382 | C82: =AVERAGEIFS('DATOS LIMPIOS'!$M$5:$M$493,'DATOS LIMPIOS'!$T$5:$T$493,"Agosto",'DATOS LIMPIOS'!$AH$5:$AH$493,"Sí") -> 22.687529
A83: Septiembre | B83: =AVERAGEIFS('DATOS LIMPIOS'!$M$5:$M$493,'DATOS LIMPIOS'!$T$5:$T$493,"Septiembre",'DATOS LIMPIOS'!$AH$5:$AH$493,"No") -> 32.87815 | C83: =AVERAGEIFS('DATOS LIMPIOS'!$M$5:$M$493,'DATOS LIMPIOS'!$T$5:$T$493,"Septiembre",'DATOS LIMPIOS'!$AH$5:$AH$493,"Sí") -> 16.127339
A84: Octubre | B84: =AVERAGEIFS('DATOS LIMPIOS'!$M$5:$M$493,'DATOS LIMPIOS'!$T$5:$T$493,"Octubre",'DATOS LIMPIOS'!$AH$5:$AH$493,"No") -> 33.164494 | C84: =AVERAGEIFS('DATOS LIMPIOS'!$M$5:$M$493,'DATOS LIMPIOS'!$T$5:$T$493,"Octubre",'DATOS LIMPIOS'!$AH$5:$AH$493,"Sí") -> 19.532131
A86: ¿Cambia el resultado? Sí | D86: p = < 0,001 (calculado en Python)
...

Sheet H4 TEMÁTICA HOT SALE
A1: Campañas con temática Hot Sale · descuentos, tiempo límite y Flash Sale
A2: Lo más cercano a la campaña que vamos a proponer: los correos de descuento, cómo usan el tiempo límite y cómo les fue a los Hot Sale anteriores.
A4: Qué campañas se parecen a un Hot Sale: las que hablan de descuento en el asunto o en el preheader. Son 287 de las 489. Los bloques H21 a H25 miran solo esas campañas; los siguientes, el límite de tiempo y los Hot Sale anteriores.
A7: H21 · En las campañas de descuento, ¿qué tipo de campaña funciona mejor?
A8: Aquí sí hay diferencias entre tipos: los correos de agradecimiento con descuento abren más que las ofertas exclusivas. Pero el asunto explica mucho más: el 54 % de la diferencia, contra el 5 % del tipo.
A11: Tabla H21 · Campañas de descuento: apertura y CTR por tipo de campaña
A12: Tipo | B12: Campañas | C12: Apertura (%) | D12: CTR (%)
A13: Customer Appreciation | B13: =COUNTIFS('DATOS LIMPIOS'!$B$5:$B$493,"Customer Appreciation",'DATOS LIMPIOS'!$AI$5:$AI$493,"Sí") -> 48 | C13: =AVERAGEIFS('DATOS LIMPIOS'!$M$5:$M$493,'DATOS LIMPIOS'!$B$5:$B$493,"Customer Appreciation",'DATOS LIMPIOS'!$AI$5:$AI$493,"Sí") -> 35.67256 | D13: =AVERAGEIFS('DATOS LIMPIOS'!$N$5:$N$493,'DATOS LIMPIOS'!$B$5:$B$493,"Customer Appreciation",'DATOS LIMPIOS'!$AI$5:$AI$493,"Sí") -> 10.752666
A14: Exclusive Offers | B14: =COUNTIFS('DATOS LIMPIOS'!$B$5:$B$493,"Exclusive Offers",'DATOS LIMPIOS'!$AI$5:$AI$493,"Sí") -> 79 | C14: =AVERAGEIFS('DATOS LIMPIOS'!$M$5:$M$493,'DATOS LIMPIOS'!$B$5:$B$493,"Exclusive Offers",'DATOS LIMPIOS'!$AI$5:$AI$493,"Sí") -> 27.021448 | D14: =AVERAGEIFS('DATOS LIMPIOS'!$N$5:$N$493,'DATOS LIMPIOS'!$B$5:$B$493,"Exclusive Offers",'DATOS LIMPIOS'!$AI$5:$AI$493,"Sí") -> 9.2971825
A15: Flash Sale | B15: =COUNTIFS('DATOS LIMPIOS'!$B$5:$B$493,"Flash Sale",'DATOS LIMPIOS'!$AI$5:$AI$493,"Sí") -> 81 | C15: =AVERAGEIFS('DATOS LIMPIOS'!$M$5:$M$493,'DATOS LIMPIOS'!$B$5:$B$493,"Flash Sale",'DATOS LIMPIOS'!$AI$5:$AI$493,"Sí") -> 29.440902 | D15: =AVERAGEIFS('DATOS LIMPIOS'!$N$5:$N$493,'DATOS LIMPIOS'!$B$5:$B$493,"Flash Sale",'DATOS LIMPIOS'!$AI$5:$AI$493,"Sí") -> 9.205166
A16: Holiday Discounts | B16: =COUNTIFS('DATOS LIMPIOS'!$B$5:$B$493,"Holiday Discounts",'DATOS LIMPIOS'!$AI$5:$AI$493,"Sí") -> 79 | C16: =AVERAGEIFS('DATOS LIMPIOS'!$M$5:$M$493,'DATOS LIMPIOS'!$B$5:$B$493,"Holiday Discounts",'DATOS LIMPIOS'!$AI$5:$AI$493,"Sí") -> 30.711144 | D16: =AVERAGEIFS('DATOS LIMPIOS'!$N$5:$N$493,'DATOS LIMPIOS'!$B$5:$B$493,"Holiday Discounts",'DATOS LIMPIOS'!$AI$5:$AI$493,"Sí") -> 9.055774
A18: ¿Cambia el resultado? Sí | D18: p = 0,002 (calculado en Python)
A31: H22 · En las campañas de descuento, ¿qué estilo de asunto funciona?
A32: El mismo patrón que en general, pero más marcado: el descuento con cifra es lo que más abre y el descuento con pura urgencia es lo que menos. Para un Hot Sale, el asunto tiene que decir cuánto y en qué.
A35: Tabla H22 · Campañas de descuento: apertura y CTR según el estilo del asunto
A36: Estilo | B36: Campañas | C36: Apertura (%) | D36: CTR (%)
A37: Con cifra concreta | B37: =COUNTIFS('DATOS LIMPIOS'!$AT$5:$AT$493,"Con cifra concreta",'DATOS LIMPIOS'!$AI$5:$AI$493,"Sí") -> 21 | C37: =AVERAGEIFS('DATOS LIMPIOS'!$M$5:$M$493,'DATOS LIMPIOS'!$AT$5:$AT$493,"Con cifra concreta",'DATOS LIMPIOS'!$AI$5:$AI$493,"Sí") -> 41.593593 | D37: =AVERAGEIFS('DATOS LIMPIOS'!$N$5:$N$493,'DATOS LIMPIOS'!$AT$5:$AT$493,"Con cifra concreta",'DATOS LIMPIOS'!$AI$5:$AI$493,"Sí") -> 10.640008
A38: Recompensa o sorpresa | B38: =COUNTIFS('DATOS LIMPIOS'!$AT$5:$AT$493,"Recompensa o sorpresa",'DATOS LIMPIOS'!$AI$5:$AI$493,"Sí") -> 110 | C38: =AVERAGEIFS('DATOS LIMPIOS'!$M$5:$M$493,'DATOS LIMPIOS'!$AT$5:$AT$493,"Recompensa o sorpresa",'DATOS LIMPIOS'!$AI$5:$AI$493,"Sí") -> 30.707806 | D38: =AVERAGEIFS('DATOS LIMPIOS'!$N$5:$N$493,'DATOS LIMPIOS'!$AT$5:$AT$493,"Recompensa o sorpresa",'DATOS LIMPIOS'!$AI$5:$AI$493,"Sí") -> 9.9172538
A39: Otro: beneficio o novedad | B39: =COUNTIFS('DATOS LIMPIOS'!$AT$5:$AT$493,"Otro: beneficio o novedad",'DATOS LIMPIOS'!$AI$5:$AI$493,"Sí") -> 95 | C39: =AVERAGEIFS('DATOS LIMPIOS'!$M$5:$M$493,'DATOS LIMPIOS'!$AT$5:$AT$493,"Otro: beneficio o novedad",'DATOS LIMPIOS'!$AI$5:$AI$493,"Sí") -> 32.735202 | D39: =AVERAGEIFS('DATOS LIMPIOS'!$N$5:$N$493,'DATOS LIMPIOS'!$AT$5:$AT$493,"Otro: beneficio o novedad",'DATOS LIMPIOS'!$AI$5:$AI$493,"Sí") -> 9.5296091
A40: Solo urgencia, sin cifra | B40: =COUNTIFS('DATOS LIMPIOS'!$AT$5:$AT$493,"Solo urgencia, sin cifra",'DATOS LIMPIOS'!$AI$5:$AI$493,"Sí") -> 61 | C40: =AVERAGEIFS('DATOS LIMPIOS'!$M$5:$M$493,'DATOS LIMPIOS'!$AT$5:$AT$493,"Solo urgencia, sin cifra",'DATOS LIMPIOS'!$AI$5:$AI$493,"Sí") -> 21.257416 | D40: =AVERAGEIFS('DATOS LIMPIOS'!$N$5:$N$493,'DATOS LIMPIOS'!$AT$5:$AT$493,"Solo urgencia, sin cifra",'DATOS LIMPIOS'!$AI$5:$AI$493,"Sí") -> 8.0652297
A42: ¿Cambia el resultado? Sí | D42: p = < 0,001 (calculado en Python)
A55: H23 · En las campañas de descuento, ¿importan las fechas de pago (quincena)?
A56: No. Aunque uno pensaría que los descuentos funcionan mejor cuando la gente recibe su sueldo, en estos datos la quincena no cambia cuántas personas abren un correo de descuento.
A59: Tabla H23 · Campañas de descuento: apertura y CTR según el momento del mes
A60: Momento del mes | B60: Campañas | C60: Apertura (%) | D60: CTR (%)
A61: Quincena | B61: =COUNTIFS('DATOS LIMPIOS'!$W$5:$W$493,"Quincena",'DATOS LIMPIOS'!$AI$5:$AI$493,"Sí") -> 59 | C61: =AVERAGEIFS('DATOS LIMPIOS'!$M$5:$M$493,'DATOS LIMPIOS'!$W$5:$W$493,"Quincena",'DATOS LIMPIOS'!$AI$5:$AI$493,"Sí") -> 28.696124 | D61: =AVERAGEIFS('DATOS LIMPIOS'!$N$5:$N$493,'DATOS LIMPIOS'!$W$5:$W$493,"Quincena",'DATOS LIMPIOS'!$AI$5:$AI$493,"Sí") -> 8.6609899
A62: Días después del pago | B62: =COUNTIFS('DATOS LIMPIOS'!$W$5:$W$493,"Días después del pago",'DATOS LIMPIOS'!$AI$5:$AI$493,"Sí") -> 78 | C62: =AVERAGEIFS('DATOS LIMPIOS'!$M$5:$M$493,'DATOS LIMPIOS'!$W$5:$W$493,"Días después del pago",'DATOS LIMPIOS'!$AI$5:$AI$493,"Sí") -> 30.9985 | D62: =AVERAGEIFS('DATOS LIMPIOS'!$N$5:$N$493,'DATOS LIMPIOS'!$W$5:$W$493,"Días después del pago",'DATOS LIMPIOS'!$AI$5:$AI$493,"Sí") -> 9.4686403
A63: Resto del mes | B63: =COUNTIFS('DATOS LIMPIOS'!$W$5:$W$493,"Resto del mes",'DATOS LIMPIOS'!$AI$5:$AI$493,"Sí") -> 150 | C63: =AVERAGEIFS('DATOS LIMPIOS'!$M$5:$M$493,'DATOS LIMPIOS'!$W$5:$W$493,"Resto del mes",'DATOS LIMPIOS'!$AI$5:$AI$493,"Sí") -> 30.312776 | D63: =AVERAGEIFS('DATOS LIMPIOS'!$N$5:$N$493,'DATOS LIMPIOS'!$W$5:$W$493,"Resto del mes",'DATOS LIMPIOS'!$AI$5:$AI$493,"Sí") -> 9.7471841
A65: ¿Cambia el resultado? No | D65: p = 0,613 (calculado en Python)
A79: H24 · En las campañas de descuento, ¿importa el día de la semana?
A80: No. Ningún día de la semana hace que un correo de descuento abra más.
A83: Tabla H24 · Campañas de descuento: apertura y CTR por día de la semana
A84: Día | B84: Campañas | C84: Apertura (%) | D84: CTR (%)
A85: Lunes | B85: =COUNTIFS('DATOS LIMPIOS'!$U$5:$U$493,"Lunes",'DATOS LIMPIOS'!$AI$5:$AI$493,"Sí") -> 62 | C85: =AVERAGEIFS('DATOS LIMPIOS'!$M$5:$M$493,'DATOS LIMPIOS'!$U$5:$U$493,"Lunes",'DATOS LIMPIOS'!$AI$5:$AI$493,"Sí") -> 32.188424 | D85: =AVERAGEIFS('DATOS LIMPIOS'!$N$5:$N$493,'DATOS LIMPIOS'!$U$5:$U$493,"Lunes",'DATOS LIMPIOS'!$AI$5:$AI$493,"Sí") -> 9.7230436
A86: Martes | B86: =COUNTIFS('DATOS LIMPIOS'!$U$5:$U$493,"Martes",'DATOS LIMPIOS'!$AI$5:$AI$493,"Sí") -> 61 | C86: =AVERAGEIFS('DATOS LIMPIOS'!$M$5:$M$493,'DATOS LIMPIOS'!$U$5:$U$493,"Martes",'DATOS LIMPIOS'!$AI$5:$AI$493,"Sí") -> 29.75947 | D86: =AVERAGEIFS('DATOS LIMPIOS'!$N$5:$N$493,'DATOS LIMPIOS'!$U$5:$U$493,"Martes",'DATOS LIMPIOS'!$AI$5:$AI$493,"Sí") -> 9.9026915
A87: Miércoles | B87: =COUNTIFS('DATOS LIMPIOS'!$U$5:$U$493,"Miércoles",'DATOS LIMPIOS'!$AI$5:$AI$493,"Sí") -> 51 | C87: =AVERAGEIFS('DATOS LIMPIOS'!$M$5:$M$493,'DATOS LIMPIOS'!$U$5:$U$493,"Miércoles",'DATOS LIMPIOS'!$AI$5:$AI$493,"Sí") -> 31.232565 | D87: =AVERAGEIFS('DATOS LIMPIOS'!$N$5:$N$493,'DATOS LIMPIOS'!$U$5:$U$493,"Miércoles",'DATOS LIMPIOS'!$AI$5:$AI$493,"Sí") -> 9.7460809
A88: Jueves | B88: =COUNTIFS('DATOS LIMPIOS'!$U$5:$U$493,"Jueves",'DATOS LIMPIOS'!$AI$5:$AI$493,"Sí") -> 40 | C88: =AVERAGEIFS('DATOS LIMPIOS'!$M$5:$M$493,'DATOS LIMPIOS'!$U$5:$U$493,"Jueves",'DATOS LIMPIOS'!$AI$5:$AI$493,"Sí") -> 30.176602 | D88: =AVERAGEIFS('DATOS LIMPIOS'!$N$5:$N$493,'DATOS LIMPIOS'!$U$5:$U$493,"Jueves",'DATOS LIMPIOS'!$AI$5:$AI$493,"Sí") -> 9.1106082
A89: Viernes | B89: =COUNTIFS('DATOS LIMPIOS'!$U$5:$U$493,"Viernes",'DATOS LIMPIOS'!$AI$5:$AI$493,"Sí") -> 23 | C89: =AVERAGEIFS('DATOS LIMPIOS'!$M$5:$M$493,'DATOS LIMPIOS'!$U$5:$U$493,"Viernes",'DATOS LIMPIOS'!$AI$5:$AI$493,"Sí") -> 28.060257 | D89: =AVERAGEIFS('DATOS LIMPIOS'!$N$5:$N$493,'DATOS LIMPIOS'!$U$5:$U$493,"Viernes",'DATOS LIMPIOS'!$AI$5:$AI$493,"Sí") -> 8.4225011
